ERROR:TeleBot:ConnectionError occurred, args=(ProtocolError('Connection aborted.', ConnectionResetError(10054, 'Удаленный хост принудительно разорвал существующее подключение', None, 10054, None)),)
Traceback (most recent call last):
  File "C:\Users\Anodmitry\AppData\Local\Programs\Python\Python35\lib\site-packages\urllib3\connectionpool.py", line 600, in urlopen
    chunked=chunked)
  File "C:\Users\Anodmitry\AppData\Local\Programs\Python\Python35\lib\site-packages\urllib3\connectionpool.py", line 343, in _make_request
    self._validate_conn(conn)
  File "C:\Users\Anodmitry\AppData\Local\Programs\Python\Python35\lib\site-packages\urllib3\connectionpool.py", line 839, in _validate_conn
    conn.connect()
  File "C:\Users\Anodmitry\AppData\Local\Programs\Python\Python35\lib\site-packages\urllib3\connection.py", line 344, in connect
    ssl_context=context)
  File "C:\Users\Anodmitry\AppData\Local\Programs\Python\Python35\lib\site-packages\urllib3\util\ssl_.py", line 344, in ssl_wrap_socket
    return context.wrap_socket(sock, server_hostname=server_hostname)
  File "C:\Users\Anodmitry\AppData\Local\Programs\Python\Python35\lib\ssl.py", line 376, in wrap_socket
    _context=self)
  File "C:\Users\Anodmitry\AppData\Local\Programs\Python\Python35\lib\ssl.py", line 747, in __init__
    self.do_handshake()
  File "C:\Users\Anodmitry\AppData\Local\Programs\Python\Python35\lib\ssl.py", line 983, in do_handshake
    self._sslobj.do_handshake()
  File "C:\Users\Anodmitry\AppData\Local\Programs\Python\Python35\lib\ssl.py", line 628, in do_handshake
    self._sslobj.do_handshake()
ConnectionResetError: [WinError 10054] Удаленный хост принудительно разорвал существующее подключение

During handling of the above exception, another exception occurred:

Traceback (most recent call last):
  File "C:\Users\Anodmitry\AppData\Local\Programs\Python\Python35\lib\site-packages\requests\adapters.py", line 449, in send
    timeout=timeout
  File "C:\Users\Anodmitry\AppData\Local\Programs\Python\Python35\lib\site-packages\urllib3\connectionpool.py", line 638, in urlopen
    _stacktrace=sys.exc_info()[2])
  File "C:\Users\Anodmitry\AppData\Local\Programs\Python\Python35\lib\site-packages\urllib3\util\retry.py", line 367, in increment
    raise six.reraise(type(error), error, _stacktrace)
  File "C:\Users\Anodmitry\AppData\Local\Programs\Python\Python35\lib\site-packages\urllib3\packages\six.py", line 685, in reraise
    raise value.with_traceback(tb)
  File "C:\Users\Anodmitry\AppData\Local\Programs\Python\Python35\lib\site-packages\urllib3\connectionpool.py", line 600, in urlopen
    chunked=chunked)
  File "C:\Users\Anodmitry\AppData\Local\Programs\Python\Python35\lib\site-packages\urllib3\connectionpool.py", line 343, in _make_request
    self._validate_conn(conn)
  File "C:\Users\Anodmitry\AppData\Local\Programs\Python\Python35\lib\site-packages\urllib3\connectionpool.py", line 839, in _validate_conn
    conn.connect()
  File "C:\Users\Anodmitry\AppData\Local\Programs\Python\Python35\lib\site-packages\urllib3\connection.py", line 344, in connect
    ssl_context=context)
  File "C:\Users\Anodmitry\AppData\Local\Programs\Python\Python35\lib\site-packages\urllib3\util\ssl_.py", line 344, in ssl_wrap_socket
    return context.wrap_socket(sock, server_hostname=server_hostname)
  File "C:\Users\Anodmitry\AppData\Local\Programs\Python\Python35\lib\ssl.py", line 376, in wrap_socket
    _context=self)
  File "C:\Users\Anodmitry\AppData\Local\Programs\Python\Python35\lib\ssl.py", line 747, in __init__
    self.do_handshake()
  File "C:\Users\Anodmitry\AppData\Local\Programs\Python\Python35\lib\ssl.py", line 983, in do_handshake
    self._sslobj.do_handshake()
  File "C:\Users\Anodmitry\AppData\Local\Programs\Python\Python35\lib\ssl.py", line 628, in do_handshake
    self._sslobj.do_handshake()
urllib3.exceptions.ProtocolError: ('Connection aborted.', ConnectionResetError(10054, 'Удаленный хост принудительно разорвал существующее подключение', None, 10054, None))

During handling of the above exception, another exception occurred:

Traceback (most recent call last):
  File "C:\Users\Anodmitry\AppData\Local\Programs\Python\Python35\lib\site-packages\telebot\util.py", line 59, in run
    task(*args, **kwargs)
  File "C:\Users\Anodmitry\AppData\Local\Programs\Python\Python35\lib\site-packages\telebot\__init__.py", line 276, in __retrieve_updates
    updates = self.get_updates(offset=(self.last_update_id + 1), timeout=timeout)
  File "C:\Users\Anodmitry\AppData\Local\Programs\Python\Python35\lib\site-packages\telebot\__init__.py", line 246, in get_updates
    json_updates = apihelper.get_updates(self.token, offset, limit, timeout, allowed_updates)
  File "C:\Users\Anodmitry\AppData\Local\Programs\Python\Python35\lib\site-packages\telebot\apihelper.py", line 180, in get_updates
    return _make_request(token, method_url, params=payload)
  File "C:\Users\Anodmitry\AppData\Local\Programs\Python\Python35\lib\site-packages\telebot\apihelper.py", line 54, in _make_request
    timeout=(connect_timeout, read_timeout), proxies=proxy)
  File "C:\Users\Anodmitry\AppData\Local\Programs\Python\Python35\lib\site-packages\requests\sessions.py", line 533, in request
    resp = self.send(prep, **send_kwargs)
  File "C:\Users\Anodmitry\AppData\Local\Programs\Python\Python35\lib\site-packages\requests\sessions.py", line 646, in send
    r = adapter.send(request, **kwargs)
  File "C:\Users\Anodmitry\AppData\Local\Programs\Python\Python35\lib\site-packages\requests\adapters.py", line 498, in send
    raise ConnectionError(err, request=request)
requests.exceptions.ConnectionError: ('Connection aborted.', ConnectionResetError(10054, 'Удаленный хост принудительно разорвал существующее подключение', None, 10054, None))

CRITICAL:root:2019-03-31 00:31:36.885582
CRITICAL:root:(ProtocolError('Connection aborted.', ConnectionResetError(10054, 'Удаленный хост принудительно разорвал существующее подключение', None, 10054, None)),)
